# AUDIT REPORT

**File**: `tests/integration/profile/test_profile_conflict.py`
**Status**: FAIL
**Audit Date**: 2025-10-19 15:15:41
**Execution Time**: 11.61s

---

## Violations (1)

- Line 0: I'll analyze this code against the comprehensive violation patterns.

**Analysis:**

1. **Line 54**: `subprocess.run(["fuser", str(profile_dir)], capture_output=True, text=True, timeout=2, check=False)` - **Violation #42**: Subprocess Exit Code Ignored. The `check=False` parameter and no exit code validation means subprocess failures are ignored.

2. **Line 63**: Exception handling suppresses the exception after logging with `raise` - Actually this is correct, the `raise` re-raises the exception.

3. **Line 69-75**: Finally block cleanup - These cleanup operations lack exception handling. If `terminate()` or `delete_profile()` or `shutdown()` raise exceptions, they will mask the original exception in the try block.

4. **Line 60**: `logger.info(f"fuser result: returncode={result.returncode}, ...")` - The code logs the result but never validates it or handles failure cases. The subprocess could fail entirely (timeout, command not found) and execution continues.

**Verdict:**

```
FAIL: Line 54: Subprocess Exit Code Ignored (check=False, no validation); Line 69-75: Finally block cleanup operations lack exception handling, will mask original exceptions
```
 (severity: CRITICAL)
