# AUDIT REPORT

**File**: `backend/utils/threading.py`
**Status**: FAIL
**Audit Date**: 2025-10-19 14:53:47
**Execution Time**: 5.43s

---

## Violations (1)

- Line 0: FAIL: Line 24: Exception → logger.debug() Without Raise (Pattern #39); Line 24: Exception → False Return (Pattern #22); Line 55: Exception → None Return (Pattern #43) - exception stored but execution continues with None result; Line 62: Missing Exception Handling (Pattern #25) - asyncio.get_running_loop() can raise RuntimeError but not wrapped in try/except at call site
 (severity: CRITICAL)
